DRIVER - Debug mode enabled
PUB139907987614928<A,B,C> - - Try to connect with ZooKeeper server: hosts = 10.0.0.1:2181
PUB139907987614928<A,B,C> - - ZooKeeper Current Status = LOST
Connection dropped: socket connection error: No route to host
Connection dropped: socket connection error: No route to host
Connection dropped: socket connection error: No route to host
Connection dropped: socket connection error: No route to host
Connection dropped: socket connection error: No route to host
Failed connecting to Zookeeper within the connection retry policy.
PUB139907987614928<A,B,C> - - Exception thrown in start (): <class 'kazoo.handlers.threading.KazooTimeoutError'>
PUB139907987614928<A,B,C> - - Checking if /broker exists (it better be)
Traceback (most recent call last):
  File "/mnt/dev/assign2/src/lib/publisher.py", line 75, in get_znode_value
    if self.zk.exists (self.zk_name):
  File "/usr/lib/python3.8/site-packages/kazoo/client.py", line 1123, in exists
    return self.exists_async(path, watch=watch).get()
  File "/usr/lib/python3.8/site-packages/kazoo/handlers/utils.py", line 69, in get
    raise self._exception
kazoo.exceptions.ConnectionClosedError: Connection has been closed

During handling of the above exception, another exception occurred:

Traceback (most recent call last):
  File "driver.py", line 251, in <module>
    publishers = create_publishers(
  File "driver.py", line 50, in create_publishers
    create_publisher_with_zookeeper(pubs[i])
  File "driver.py", line 11, in create_publisher_with_zookeeper
    publisher.get_znode_value()
  File "/mnt/dev/assign2/src/lib/publisher.py", line 86, in get_znode_value
    self.debug("Exception thrown checking for exists/get: ", sys.exc_info()[0])
TypeError: debug() takes 2 positional arguments but 3 were given
